


Scanning images: 100%|█████████████████████████████████| 477/477 [00:05<00:00, 80.88it/s]
Scanning labels /media/tlab/Data/Dataset/Carm/wire/txt.cache3 (477 found, 0 missing, 0 empty, 0 duplicate, for 477 images): 477it [00:00, 28581.59it/s]

Scanning images: 100%|█████████████████████████████████| 318/318 [00:03<00:00, 90.06it/s]
Scanning labels /media/tlab/Data/Dataset/Carm/wire/txt.cache3 (318 found, 0 missing, 0 empty, 0 duplicate, for 318 images): 318it [00:00, 15546.59it/s]
Images sizes do not match. This will causes images to be display incorrectly in the UI.
Image sizes 512 train, 512 test
Using 8 dataloader workers
Logging results to runs/train/yolov4
Starting training for 300 epochs...
     Epoch   gpu_mem       box       obj       cls     total   targets  img_size
     0/299     12.6G    0.1172   0.03352   0.01792    0.1687        97       512:   3%| |
Traceback (most recent call last):
  File "train.py", line 537, in <module>
    train(hyp, opt, device, tb_writer, wandb)
  File "train.py", line 287, in train
    pred = model(imgs)  # forward
  File "/home/tlab/anaconda3/envs/yo/lib/python3.7/site-packages/torch/nn/modules/module.py", line 889, in _call_impl
    result = self.forward(*input, **kwargs)
  File "/home/tlab/Tlab/pytorch/ObjectDetection/YOLOV4/models/models.py", line 464, in forward
    return self.forward_once(x)
  File "/home/tlab/Tlab/pytorch/ObjectDetection/YOLOV4/models/models.py", line 523, in forward_once
    x = module(x)
  File "/home/tlab/anaconda3/envs/yo/lib/python3.7/site-packages/torch/nn/modules/module.py", line 889, in _call_impl
    result = self.forward(*input, **kwargs)
  File "/home/tlab/anaconda3/envs/yo/lib/python3.7/site-packages/torch/nn/modules/container.py", line 119, in forward
    input = module(input)
  File "/home/tlab/anaconda3/envs/yo/lib/python3.7/site-packages/torch/nn/modules/module.py", line 889, in _call_impl
    result = self.forward(*input, **kwargs)
  File "/home/tlab/anaconda3/envs/yo/lib/python3.7/site-packages/torch/nn/modules/conv.py", line 399, in forward
    return self._conv_forward(input, self.weight, self.bias)
  File "/home/tlab/anaconda3/envs/yo/lib/python3.7/site-packages/torch/nn/modules/conv.py", line 396, in _conv_forward
    self.padding, self.dilation, self.groups)
RuntimeError: CUDA out of memory. Tried to allocate 20.00 MiB (GPU 0; 23.70 GiB total capacity; 22.17 GiB already allocated; 11.38 MiB free; 22.24 GiB reserved in total by PyTorch)